<?xml version="1.0" encoding="UTF-8"?>
<testng-results skipped="0" failed="4" total="4" passed="0">
  <reporter-output>
  </reporter-output>
  <suite name="Default suite" duration-ms="23654" started-at="2016-10-23T22:40:22Z" finished-at="2016-10-23T22:40:46Z">
    <groups>
    </groups>
    <test name="Default test" duration-ms="23654" started-at="2016-10-23T22:40:22Z" finished-at="2016-10-23T22:40:46Z">
      <class name="relayr.login.NewTest">
        <test-method status="PASS" signature="setup()[pri:0, instance:relayr.login.NewTest@5c3bd550]" name="setup" is-config="true" duration-ms="12181" started-at="2016-10-24T04:10:22Z" finished-at="2016-10-24T04:10:34Z">
          <reporter-output>
          </reporter-output>
        </test-method> <!-- setup -->
        <test-method status="FAIL" signature="negativeTestEmptyMail()[pri:0, instance:relayr.login.NewTest@5c3bd550]" name="negativeTestEmptyMail" duration-ms="4689" started-at="2016-10-24T04:10:34Z" finished-at="2016-10-24T04:10:39Z">
          <exception class="java.lang.AssertionError">
            <message>
              <![CDATA[expected [Email cannot be empty.] but found [The email is not a valid email address.]]]>
            </message>
            <full-stacktrace>
              <![CDATA[java.lang.AssertionError: expected [Email cannot be empty.] but found [The email is not a valid email address.]
	at org.testng.Assert.fail(Assert.java:94)
	at org.testng.Assert.failNotEquals(Assert.java:513)
	at org.testng.Assert.assertEqualsImpl(Assert.java:135)
	at org.testng.Assert.assertEquals(Assert.java:116)
	at org.testng.Assert.assertEquals(Assert.java:190)
	at org.testng.Assert.assertEquals(Assert.java:200)
	at relayr.login.NewTest.negativeTestEmptyMail(NewTest.java:43)
	at sun.reflect.NativeMethodAccessorImpl.invoke0(Native Method)
	at sun.reflect.NativeMethodAccessorImpl.invoke(Unknown Source)
	at sun.reflect.DelegatingMethodAccessorImpl.invoke(Unknown Source)
	at java.lang.reflect.Method.invoke(Unknown Source)
	at org.testng.internal.MethodInvocationHelper.invokeMethod(MethodInvocationHelper.java:100)
	at org.testng.internal.Invoker.invokeMethod(Invoker.java:646)
	at org.testng.internal.Invoker.invokeTestMethod(Invoker.java:811)
	at org.testng.internal.Invoker.invokeTestMethods(Invoker.java:1137)
	at org.testng.internal.TestMethodWorker.invokeTestMethods(TestMethodWorker.java:129)
	at org.testng.internal.TestMethodWorker.run(TestMethodWorker.java:112)
	at org.testng.TestRunner.privateRun(TestRunner.java:753)
	at org.testng.TestRunner.run(TestRunner.java:607)
	at org.testng.SuiteRunner.runTest(SuiteRunner.java:368)
	at org.testng.SuiteRunner.runSequentially(SuiteRunner.java:363)
	at org.testng.SuiteRunner.privateRun(SuiteRunner.java:321)
	at org.testng.SuiteRunner.run(SuiteRunner.java:270)
	at org.testng.SuiteRunnerWorker.runSuite(SuiteRunnerWorker.java:52)
	at org.testng.SuiteRunnerWorker.run(SuiteRunnerWorker.java:86)
	at org.testng.TestNG.runSuitesSequentially(TestNG.java:1284)
	at org.testng.TestNG.runSuitesLocally(TestNG.java:1209)
	at org.testng.TestNG.runSuites(TestNG.java:1124)
	at org.testng.TestNG.run(TestNG.java:1096)
	at org.testng.remote.AbstractRemoteTestNG.run(AbstractRemoteTestNG.java:132)
	at org.testng.remote.RemoteTestNG.initAndRun(RemoteTestNG.java:236)
	at org.testng.remote.RemoteTestNG.main(RemoteTestNG.java:81)
]]>
            </full-stacktrace>
          </exception> <!-- java.lang.AssertionError -->
          <reporter-output>
          </reporter-output>
        </test-method> <!-- negativeTestEmptyMail -->
        <test-method status="FAIL" signature="negativeTestEmptyPassword()[pri:1, instance:relayr.login.NewTest@5c3bd550]" name="negativeTestEmptyPassword" duration-ms="51" started-at="2016-10-24T04:10:39Z" finished-at="2016-10-24T04:10:39Z">
          <exception class="java.lang.AssertionError">
            <message>
              <![CDATA[expected [Log In - Stack Overflow] but found [Stack Overflow]]]>
            </message>
            <full-stacktrace>
              <![CDATA[java.lang.AssertionError: expected [Log In - Stack Overflow] but found [Stack Overflow]
	at org.testng.Assert.fail(Assert.java:94)
	at org.testng.Assert.failNotEquals(Assert.java:513)
	at org.testng.Assert.assertEqualsImpl(Assert.java:135)
	at org.testng.Assert.assertEquals(Assert.java:116)
	at org.testng.Assert.assertEquals(Assert.java:190)
	at org.testng.Assert.assertEquals(Assert.java:200)
	at relayr.login.NewTest.negativeTestEmptyPassword(NewTest.java:47)
	at sun.reflect.NativeMethodAccessorImpl.invoke0(Native Method)
	at sun.reflect.NativeMethodAccessorImpl.invoke(Unknown Source)
	at sun.reflect.DelegatingMethodAccessorImpl.invoke(Unknown Source)
	at java.lang.reflect.Method.invoke(Unknown Source)
	at org.testng.internal.MethodInvocationHelper.invokeMethod(MethodInvocationHelper.java:100)
	at org.testng.internal.Invoker.invokeMethod(Invoker.java:646)
	at org.testng.internal.Invoker.invokeTestMethod(Invoker.java:811)
	at org.testng.internal.Invoker.invokeTestMethods(Invoker.java:1137)
	at org.testng.internal.TestMethodWorker.invokeTestMethods(TestMethodWorker.java:129)
	at org.testng.internal.TestMethodWorker.run(TestMethodWorker.java:112)
	at org.testng.TestRunner.privateRun(TestRunner.java:753)
	at org.testng.TestRunner.run(TestRunner.java:607)
	at org.testng.SuiteRunner.runTest(SuiteRunner.java:368)
	at org.testng.SuiteRunner.runSequentially(SuiteRunner.java:363)
	at org.testng.SuiteRunner.privateRun(SuiteRunner.java:321)
	at org.testng.SuiteRunner.run(SuiteRunner.java:270)
	at org.testng.SuiteRunnerWorker.runSuite(SuiteRunnerWorker.java:52)
	at org.testng.SuiteRunnerWorker.run(SuiteRunnerWorker.java:86)
	at org.testng.TestNG.runSuitesSequentially(TestNG.java:1284)
	at org.testng.TestNG.runSuitesLocally(TestNG.java:1209)
	at org.testng.TestNG.runSuites(TestNG.java:1124)
	at org.testng.TestNG.run(TestNG.java:1096)
	at org.testng.remote.AbstractRemoteTestNG.run(AbstractRemoteTestNG.java:132)
	at org.testng.remote.RemoteTestNG.initAndRun(RemoteTestNG.java:236)
	at org.testng.remote.RemoteTestNG.main(RemoteTestNG.java:81)
]]>
            </full-stacktrace>
          </exception> <!-- java.lang.AssertionError -->
          <reporter-output>
          </reporter-output>
        </test-method> <!-- negativeTestEmptyPassword -->
        <test-method status="FAIL" signature="negativeTestInvalidMail()[pri:2, instance:relayr.login.NewTest@5c3bd550]" name="negativeTestInvalidMail" duration-ms="26" started-at="2016-10-24T04:10:39Z" finished-at="2016-10-24T04:10:39Z">
          <exception class="java.lang.AssertionError">
            <message>
              <![CDATA[expected [Log In - Stack Overflow] but found [Stack Overflow]]]>
            </message>
            <full-stacktrace>
              <![CDATA[java.lang.AssertionError: expected [Log In - Stack Overflow] but found [Stack Overflow]
	at org.testng.Assert.fail(Assert.java:94)
	at org.testng.Assert.failNotEquals(Assert.java:513)
	at org.testng.Assert.assertEqualsImpl(Assert.java:135)
	at org.testng.Assert.assertEquals(Assert.java:116)
	at org.testng.Assert.assertEquals(Assert.java:190)
	at org.testng.Assert.assertEquals(Assert.java:200)
	at relayr.login.NewTest.negativeTestInvalidMail(NewTest.java:59)
	at sun.reflect.NativeMethodAccessorImpl.invoke0(Native Method)
	at sun.reflect.NativeMethodAccessorImpl.invoke(Unknown Source)
	at sun.reflect.DelegatingMethodAccessorImpl.invoke(Unknown Source)
	at java.lang.reflect.Method.invoke(Unknown Source)
	at org.testng.internal.MethodInvocationHelper.invokeMethod(MethodInvocationHelper.java:100)
	at org.testng.internal.Invoker.invokeMethod(Invoker.java:646)
	at org.testng.internal.Invoker.invokeTestMethod(Invoker.java:811)
	at org.testng.internal.Invoker.invokeTestMethods(Invoker.java:1137)
	at org.testng.internal.TestMethodWorker.invokeTestMethods(TestMethodWorker.java:129)
	at org.testng.internal.TestMethodWorker.run(TestMethodWorker.java:112)
	at org.testng.TestRunner.privateRun(TestRunner.java:753)
	at org.testng.TestRunner.run(TestRunner.java:607)
	at org.testng.SuiteRunner.runTest(SuiteRunner.java:368)
	at org.testng.SuiteRunner.runSequentially(SuiteRunner.java:363)
	at org.testng.SuiteRunner.privateRun(SuiteRunner.java:321)
	at org.testng.SuiteRunner.run(SuiteRunner.java:270)
	at org.testng.SuiteRunnerWorker.runSuite(SuiteRunnerWorker.java:52)
	at org.testng.SuiteRunnerWorker.run(SuiteRunnerWorker.java:86)
	at org.testng.TestNG.runSuitesSequentially(TestNG.java:1284)
	at org.testng.TestNG.runSuitesLocally(TestNG.java:1209)
	at org.testng.TestNG.runSuites(TestNG.java:1124)
	at org.testng.TestNG.run(TestNG.java:1096)
	at org.testng.remote.AbstractRemoteTestNG.run(AbstractRemoteTestNG.java:132)
	at org.testng.remote.RemoteTestNG.initAndRun(RemoteTestNG.java:236)
	at org.testng.remote.RemoteTestNG.main(RemoteTestNG.java:81)
]]>
            </full-stacktrace>
          </exception> <!-- java.lang.AssertionError -->
          <reporter-output>
          </reporter-output>
        </test-method> <!-- negativeTestInvalidMail -->
        <test-method status="FAIL" signature="positiveTest()[pri:3, instance:relayr.login.NewTest@5c3bd550]" name="positiveTest" duration-ms="4765" started-at="2016-10-24T04:10:39Z" finished-at="2016-10-24T04:10:44Z">
          <exception class="java.lang.AssertionError">
            <message>
              <![CDATA[expected [true] but found [false]]]>
            </message>
            <full-stacktrace>
              <![CDATA[java.lang.AssertionError: expected [true] but found [false]
	at org.testng.Assert.fail(Assert.java:94)
	at org.testng.Assert.failNotEquals(Assert.java:513)
	at org.testng.Assert.assertTrue(Assert.java:42)
	at org.testng.Assert.assertTrue(Assert.java:52)
	at relayr.login.NewTest.positiveTest(NewTest.java:31)
	at sun.reflect.NativeMethodAccessorImpl.invoke0(Native Method)
	at sun.reflect.NativeMethodAccessorImpl.invoke(Unknown Source)
	at sun.reflect.DelegatingMethodAccessorImpl.invoke(Unknown Source)
	at java.lang.reflect.Method.invoke(Unknown Source)
	at org.testng.internal.MethodInvocationHelper.invokeMethod(MethodInvocationHelper.java:100)
	at org.testng.internal.Invoker.invokeMethod(Invoker.java:646)
	at org.testng.internal.Invoker.invokeTestMethod(Invoker.java:811)
	at org.testng.internal.Invoker.invokeTestMethods(Invoker.java:1137)
	at org.testng.internal.TestMethodWorker.invokeTestMethods(TestMethodWorker.java:129)
	at org.testng.internal.TestMethodWorker.run(TestMethodWorker.java:112)
	at org.testng.TestRunner.privateRun(TestRunner.java:753)
	at org.testng.TestRunner.run(TestRunner.java:607)
	at org.testng.SuiteRunner.runTest(SuiteRunner.java:368)
	at org.testng.SuiteRunner.runSequentially(SuiteRunner.java:363)
	at org.testng.SuiteRunner.privateRun(SuiteRunner.java:321)
	at org.testng.SuiteRunner.run(SuiteRunner.java:270)
	at org.testng.SuiteRunnerWorker.runSuite(SuiteRunnerWorker.java:52)
	at org.testng.SuiteRunnerWorker.run(SuiteRunnerWorker.java:86)
	at org.testng.TestNG.runSuitesSequentially(TestNG.java:1284)
	at org.testng.TestNG.runSuitesLocally(TestNG.java:1209)
	at org.testng.TestNG.runSuites(TestNG.java:1124)
	at org.testng.TestNG.run(TestNG.java:1096)
	at org.testng.remote.AbstractRemoteTestNG.run(AbstractRemoteTestNG.java:132)
	at org.testng.remote.RemoteTestNG.initAndRun(RemoteTestNG.java:236)
	at org.testng.remote.RemoteTestNG.main(RemoteTestNG.java:81)
]]>
            </full-stacktrace>
          </exception> <!-- java.lang.AssertionError -->
          <reporter-output>
          </reporter-output>
        </test-method> <!-- positiveTest -->
        <test-method status="PASS" signature="close()[pri:0, instance:relayr.login.NewTest@5c3bd550]" name="close" is-config="true" duration-ms="1833" started-at="2016-10-24T04:10:44Z" finished-at="2016-10-24T04:10:46Z">
          <reporter-output>
          </reporter-output>
        </test-method> <!-- close -->
      </class> <!-- relayr.login.NewTest -->
    </test> <!-- Default test -->
  </suite> <!-- Default suite -->
</testng-results>
